<?xml version="1.0" encoding="utf-8"?>
<robot name="iiwa7">
  <link name="link_0_arm">
    <inertial>
      <origin rpy="0 0 0" xyz="-0.012857 0.0 0.069964"/>
      <mass value="4.855658"/>
      <inertia ixx="0.017839" ixy="0.0" ixz="0.000781" iyy="0.022294" iyz="0.0" izz="0.021334"/>
    </inertial>
    <visual>
      <origin rpy="0 0 0" xyz="0 0 0"/>
      <geometry>
        <mesh filename="meshes/visual/link_0.glb"/>
      </geometry>
    </visual>
    <collision>
      <origin rpy="0 0 0" xyz="0 0 0"/>
      <geometry>
        <mesh filename="meshes/collision/link_0.obj"/>
      </geometry>
    </collision>
  </link>
  <joint name="A1" type="revolute">
    <origin rpy="0 0 0" xyz="0.0 0.0 0.1475"/>
    <parent link="link_0_arm"/>
    <child link="link_1_arm"/>
    <axis xyz="0.0 0.0 1.0"/>
    <limit effort="200" lower="-2.96705972839" upper="2.96705972839" velocity="1.71042266695"/>
    <dynamics damping="10.0" friction="0.1"/>
  </joint>
  <link name="link_1_arm">
    <inertial>
      <origin rpy="0 0 0" xyz="0.0 -0.034819 0.123299"/>
      <mass value="3.394011"/>
      <inertia ixx="0.021383" ixy="0.0" ixz="0.0" iyy="0.020403" iyz="0.003797" izz="0.007563"/>
    </inertial>
    <visual>
      <origin rpy="0 0 0" xyz="0.0 0.0 -0.1475"/>
      <geometry>
        <mesh filename="meshes/visual/link_1.glb"/>
      </geometry>
    </visual>
    <collision>
      <origin rpy="0 0 0" xyz="0.0 0.0 -0.1475"/>
      <geometry>
        <mesh filename="meshes/collision/link_1.obj"/>
      </geometry>
    </collision>
  </link>
  <joint name="A2" type="revolute">
    <origin rpy="0 0 0" xyz="0.0 -0.0105 0.1925"/>
    <parent link="link_1_arm"/>
    <child link="link_2_arm"/>
    <axis xyz="0.0 1.0 0.0"/>
    <limit effort="200" lower="-2.09439510239" upper="2.09439510239" velocity="1.71042266695"/>
    <dynamics damping="10.0" friction="0.1"/>
  </joint>
  <link name="link_2_arm">
    <inertial>
      <origin rpy="0 0 0" xyz="0.0 0.039793 0.086944"/>
      <mass value="4.031991"/>
      <inertia ixx="0.031697" ixy="0.0" ixz="0.0" iyy="0.03008" iyz="0.005889" izz="0.009666"/>
    </inertial>
    <visual>
      <origin rpy="0 0 0" xyz="0.0 0.0105 -0.34"/>
      <geometry>
        <mesh filename="meshes/visual/link_2.glb"/>
      </geometry>
    </visual>
    <collision>
      <origin rpy="0 0 0" xyz="0.0 0.0105 -0.34"/>
      <geometry>
        <mesh filename="meshes/collision/link_2.obj"/>
      </geometry>
    </collision>
  </link>
  <joint name="A3" type="revolute">
    <origin rpy="0 0 0" xyz="0.0 0.0105 0.2075"/>
    <parent link="link_2_arm"/>
    <child link="link_3_arm"/>
    <axis xyz="0.0 0.0 1.0"/>
    <limit effort="200" lower="-2.96705972839" upper="2.96705972839" velocity="1.74532925199"/>
    <dynamics damping="10.0" friction="0.1"/>
  </joint>
  <link name="link_3_arm">
    <inertial>
      <origin rpy="0 0 0" xyz="0.0 0.034819 0.123299"/>
      <mass value="3.394011"/>
      <inertia ixx="0.021383" ixy="0.0" ixz="0.0" iyy="0.020403" iyz="-0.003797" izz="0.007563"/>
    </inertial>
    <visual>
      <origin rpy="0 0 0" xyz="0.0 0.0 -0.5475"/>
      <geometry>
        <mesh filename="meshes/visual/link_3.glb"/>
      </geometry>
    </visual>
    <collision>
      <origin rpy="0 0 0" xyz="0.0 0.0 -0.5475"/>
      <geometry>
        <mesh filename="meshes/collision/link_3.obj"/>
      </geometry>
    </collision>
  </link>
  <joint name="A4" type="revolute">
    <origin rpy="0 0 0" xyz="0.0 0.0105 0.1925"/>
    <parent link="link_3_arm"/>
    <child link="link_4_arm"/>
    <axis xyz="0.0 -1.0 0.0"/>
    <limit effort="200" lower="-2.09439510239" upper="2.09439510239" velocity="2.26892802759"/>
    <dynamics damping="10.0" friction="0.1"/>
  </joint>
  <link name="link_4_arm">
    <inertial>
      <origin rpy="0 0 0" xyz="0.0 -0.039793 0.086944"/>
      <mass value="4.031989"/>
      <inertia ixx="0.031695" ixy="0.0" ixz="0.0" iyy="0.030079" iyz="-0.005889" izz="0.009665"/>
    </inertial>
    <visual>
      <origin rpy="0 0 0" xyz="0.0 -0.0105 -0.74"/>
      <geometry>
        <mesh filename="meshes/visual/link_4.glb"/>
      </geometry>
    </visual>
    <collision>
      <origin rpy="0 0 0" xyz="0.0 -0.0105 -0.74"/>
      <geometry>
        <mesh filename="meshes/collision/link_4.obj"/>
      </geometry>
    </collision>
  </link>
  <joint name="A5" type="revolute">
    <origin rpy="0 0 0" xyz="0.0 -0.0105 0.2075"/>
    <parent link="link_4_arm"/>
    <child link="link_5_arm"/>
    <axis xyz="0.0 0.0 1.0"/>
    <limit effort="200" lower="-2.96705972839" upper="2.96705972839" velocity="2.44346095279"/>
    <dynamics damping="10.0" friction="0.1"/>
  </joint>
  <link name="link_5_arm">
    <inertial>
      <origin rpy="0 0 0" xyz="0.0 -0.029824 0.076267"/>
      <mass value="1.529239"/>
      <inertia ixx="0.008485" ixy="0.0" ixz="0.0" iyy="0.007136" iyz="0.002806" izz="0.003848"/>
    </inertial>
    <visual>
      <origin rpy="0 0 0" xyz="0.0 0.0 -0.9475"/>
      <geometry>
        <mesh filename="meshes/visual/link_5.glb"/>
      </geometry>
    </visual>
    <collision>
      <origin rpy="0 0 0" xyz="0.0 0.0 -0.9475"/>
      <geometry>
        <mesh filename="meshes/collision/link_5.obj"/>
      </geometry>
    </collision>
  </link>
  <joint name="A6" type="revolute">
    <origin rpy="0 0 0" xyz="0.0 -0.0707 0.1925"/>
    <parent link="link_5_arm"/>
    <child link="link_6_arm"/>
    <axis xyz="0.0 1.0 0.0"/>
    <limit effort="200" lower="-2.09439510239" upper="2.09439510239" velocity="3.14159265359"/>
    <dynamics damping="10.0" friction="0.1"/>
  </joint>
  <link name="link_6_arm">
    <inertial>
      <origin rpy="0 0 0" xyz="0.0 0.07102 0.00495"/>
      <mass value="2.403626"/>
      <inertia ixx="0.007067" ixy="0.0" ixz="0.0" iyy="0.006804" iyz="0.000311" izz="0.004629"/>
    </inertial>
    <visual>
      <origin rpy="0 0 0" xyz="0.0 0.0707 -1.14"/>
      <geometry>
        <mesh filename="meshes/visual/link_6.glb"/>
      </geometry>
    </visual>
    <collision>
      <origin rpy="0 0 0" xyz="0.0 0.0707 -1.14"/>
      <geometry>
        <mesh filename="meshes/collision/link_6.obj"/>
      </geometry>
    </collision>
  </link>
  <joint name="A7" type="revolute">
    <origin rpy="0 0 0" xyz="0.0 0.0707 0.091"/>
    <parent link="link_6_arm"/>
    <child link="link_7_arm"/>
    <axis xyz="0.0 0.0 1.0"/>
    <limit effort="200" lower="-3.05432619099" upper="3.05432619099" velocity="3.14159265359"/>
    <dynamics damping="10.0" friction="0.1"/>
  </joint>
  <link name="link_7_arm">
    <inertial>
      <origin rpy="0 0 0" xyz="3.0000e-06 -2.0000e-06 1.3782e-02"/>
      <mass value="0.259474"/>
      <inertia ixx="0.000171" ixy="0.0" ixz="0.0" iyy="0.000171" iyz="0.0" izz="0.000299"/>
    </inertial>
    <visual>
      <origin rpy="0 0 0" xyz="0.0 0.0 -1.231"/>
      <geometry>
        <mesh filename="meshes/visual/link_7.glb"/>
      </geometry>
    </visual>
    <collision>
      <origin rpy="0 0 0" xyz="0.0 0.0 -1.231"/>
      <geometry>
        <mesh filename="meshes/collision/link_7.obj"/>
      </geometry>
    </collision>
  </link>

  <joint name="joint_eef" type="fixed">
    <origin xyz="0 0 0.13" rpy="0 0 0"/>
    <parent link="link_7_arm"/>
    <child link="base_link_hand"/>
  </joint>

<!-- ============================================================================= -->
  <!-- FINGERS -->
  <!-- RIGHT HAND due to which finger is number 0 -->
  <!-- for LEFT HAND switch the sign of the **offset_origin_y** and **finger_angle_r** parameters-->
  <link name="base_link_hand">
    <inertial>
      <mass value="0.4154"/>
      <origin rpy="0 0 0" xyz="0 0 0"/>
      <inertia ixx="1e-4" ixy="0" ixz="0" iyy="1e-4" iyz="0" izz="1e-4"/>
    </inertial>
    <visual>
      <geometry>
        <mesh filename="../allegro_hand/meshes/visual/base_link.glb"/>
      </geometry>
      <origin rpy="0 0 0" xyz="0 0 0 "/>
    </visual>
    <collision>
      <origin rpy="0 0 0" xyz="-0.009 0.0 -0.023"/>
      <geometry>
        <box size="0.0414 0.112 0.0448"/>
      </geometry>
    </collision>
    <collision>
      <origin rpy="0 0 0" xyz="-0.009 -0.0253 -0.0667"/>
      <geometry>
        <box size="0.0414 0.0538 0.0428"/>
      </geometry>
    </collision>
    <collision>
      <origin rpy="0 0 0" xyz="-0.009300 -0.00557 -0.08874"/>
      <geometry>
        <box size="0.0414 0.0720 0.013"/>
      </geometry>
    </collision>
  </link> 
  
  <!--  virtual link-->
  <link name="palm"/>
  <joint name="palm_joint" type="fixed">
    <parent link="base_link_hand"/>
    <child link="palm"/>
    <origin rpy="0.00000 -0.00000 0.00000" xyz="0 0 -0.065"/>
  </joint> 

  <!--  virtual link-->
  <link name="wrist"/>
  <joint name="wrist_joint" type="fixed">
    <origin rpy="0 0 0" xyz="0 0 -0.03"/>
    <parent link="palm"/>
    <child link="wrist"/>
  </joint>

  <link name="link_0">
    <visual>
      <geometry>
        <mesh filename="../allegro_hand/meshes/visual/link_0.0.glb"/>
      </geometry>
    </visual>
    <collision>
      <geometry>
        <box size="0.0196 0.0275 0.0164"/>
      </geometry>
      <origin rpy="0 0 0" xyz="0 0 0.0082"/>
    </collision>
    <inertial>
      <mass value="0.0119"/>
      <origin xyz="0 0 0" rpy="0 0 0"/>
      <inertia ixx="1.01666658333e-06" ixy="0.0" ixz="0.0" iyy="6.47677333333e-07" iyz="0.0" izz="1.01666658333e-06"/>
    </inertial>
  </link>
  <joint name="joint_0" type="revolute">
    <axis xyz="0 0 1"/>
    <limit effort="10" lower="-0.47" upper="0.47" velocity="3.14"/>
    <parent link="base_link_hand"/>
    <child link="link_0"/>
    <origin rpy="-0.08726646255 0 0" xyz="0 0.0435 -0.001542"/>
  </joint>
  <link name="link_1">
    <inertial>
      <mass value="0.065"/>
      <origin xyz="0 0 0" rpy="0 0 0"/>
      <inertia ixx="7.95654166667e-05" ixy="1.7199e-05" ixz="8.75875e-06" iyy="2.47088833333e-05" iyz="2.413125e-05" izz="7.95654166667e-05"/>
    </inertial>
    <visual>
      <geometry>
        <mesh filename="../allegro_hand/meshes/visual/link_1.0.glb"/>
      </geometry>
    </visual>
    <collision>
      <geometry>
        <box size="0.0196 0.0275 0.054"/>
      </geometry>
      <origin rpy="0 0 0" xyz="0 0 0.027"/>
    </collision>
  </link>
  <joint name="joint_1" type="revolute">
    <limit effort="10" lower="-0.196" upper="1.61" velocity="3.14"/>
    <axis xyz="0 1 0"/>
    <parent link="link_0"/>
    <child link="link_1"/>
    <origin xyz="0 0 0.0164"/>
  </joint>
  <link name="link_2">
    <inertial>
      <mass value="0.0355"/>
      <origin xyz="0 0 0" rpy="0 0 0"/>
      <inertia ixx="2.63979183333e-05" ixy="6.67968e-06" ixz="4.783625e-06" iyy="1.34948516667e-05" iyz="9.372e-06" izz="2.63979183333e-05"/>
    </inertial>
    <visual>
      <geometry>
        <mesh filename="../allegro_hand/meshes/visual/link_2.0.glb"/>
      </geometry>
    </visual>
    <collision>
      <geometry>
        <box size="0.0196 0.0275 0.0384"/>
      </geometry>
      <origin rpy="0 0 0" xyz="0 0 0.0192"/>
    </collision>
  </link>
  <joint name="joint_2" type="revolute">
    <axis xyz="0 1 0"/>
    <limit effort="10" lower="-0.174" upper="1.709" velocity="3.14"/>
    <parent link="link_1"/>
    <child link="link_2"/>
    <origin xyz="0 0 0.054"/>
  </joint>
  <link name="link_3">
    <visual>
      <geometry>
        <mesh filename="../allegro_hand/meshes/visual/link_3.0.glb"/>
      </geometry>
    </visual>
    <collision>
      <geometry>
        <box size="0.0196 0.0269 0.022"/>
      </geometry>
      <origin rpy="0 0 0" xyz="0 0 0.0047"/>
    </collision>
    <inertial>
      <origin rpy="0 0 0" xyz="0 0 0.01335"/>
      <mass value="0.02"/>
      <inertia ixx="1e-5" ixy="0.0" ixz="0.0" iyy="2e-5" iyz="0.0" izz="2e-5"/>
    </inertial>
  </link>
  <joint name="joint_3" type="revolute">
    <axis xyz="0 1 0"/>
    <limit effort="10" lower="-0.227" upper="1.618" velocity="3.14"/>
    <parent link="link_2"/>
    <child link="link_3"/>
    <origin xyz="0 0 0.0384"/>
  </joint>
  <link name="link_3_tip">
    <inertial>
      <mass value="0.0168"/>
      <origin xyz="0 0 0" rpy="0 0 0"/>
      <inertia ixx="9.68e-07" ixy="0" ixz="0" iyy="9.68e-07" iyz="0" izz="9.68e-07"/>
    </inertial>
    <visual>
      <geometry>
        <mesh filename="../allegro_hand/meshes/visual/link_tip.glb"/>
      </geometry>
    </visual>
    <collision>
      <geometry>
        <mesh filename="../allegro_hand/meshes/collision/link_tip.obj"/>
      </geometry>
    </collision>
  </link>
  <joint name="joint_3_tip" type="fixed">
    <parent link="link_3"/>
    <child link="link_3_tip"/>
    <origin rpy="0 0 0" xyz="0 0 0.0267"/>
  </joint>
  <link name="link_4">
    <inertial>
      <mass value="0.005"/>
      <origin xyz="0 0 0"/>
      <inertia ixx="5.1458e-05" iyy="5.1458e-05" izz="6.125e-05" ixy="0" ixz="0" iyz="0"/>
    </inertial>
    <visual>
      <geometry>
        <mesh filename="../allegro_hand/meshes/visual/link_0.0.glb"/>
      </geometry>
    </visual>
    <collision>
      <geometry>
        <box size="0.0196 0.0275 0.0164"/>
      </geometry>
      <origin rpy="0 0 0" xyz="0 0 0.0082"/>
    </collision>
  </link>
  <joint name="joint_4" type="revolute">
    <axis xyz="0 0 1"/>
    <limit effort="10" lower="-0.47" upper="0.47" velocity="3.14"/>
    <parent link="base_link_hand"/>
    <child link="link_4"/>
    <origin rpy="0.0 0 0" xyz="0 0 0.0007"/>
  </joint>
  <link name="link_5">
    <inertial>
      <mass value="0.065"/>
      <origin xyz="0 0 0" rpy="0 0 0"/>
      <inertia ixx="7.95654166667e-05" ixy="1.7199e-05" ixz="8.75875e-06" iyy="2.47088833333e-05" iyz="2.413125e-05" izz="7.95654166667e-05"/>
    </inertial>
    <visual>
      <geometry>
        <mesh filename="../allegro_hand/meshes/visual/link_1.0.glb"/>
      </geometry>
    </visual>
    <collision>
      <geometry>
        <box size="0.0196 0.0275 0.054"/>
      </geometry>
      <origin rpy="0 0 0" xyz="0 0 0.027"/>
    </collision>
  </link>
  <joint name="joint_5" type="revolute">
    <limit effort="10" lower="-0.196" upper="1.61" velocity="3.14"/>
    <axis xyz="0 1 0"/>
    <parent link="link_4"/>
    <child link="link_5"/>
    <origin xyz="0 0 0.0164"/>
  </joint>
  <link name="link_6">
    <inertial>
      <mass value="0.0355"/>
      <origin xyz="0 0 0" rpy="0 0 0"/>
      <inertia ixx="2.63979183333e-05" ixy="6.67968e-06" ixz="4.783625e-06" iyy="1.34948516667e-05" iyz="9.372e-06" izz="2.63979183333e-05"/>
    </inertial>
    <visual>
      <geometry>
        <mesh filename="../allegro_hand/meshes/visual/link_2.0.glb"/>
      </geometry>
    </visual>
    <collision>
      <geometry>
        <box size="0.0196 0.0275 0.0384"/>
      </geometry>
      <origin rpy="0 0 0" xyz="0 0 0.0192"/>
    </collision>
  </link>
  <joint name="joint_6" type="revolute">
    <axis xyz="0 1 0"/>
    <limit effort="10" lower="-0.174" upper="1.709" velocity="3.14"/>
    <parent link="link_5"/>
    <child link="link_6"/>
    <origin xyz="0 0 0.054"/>
  </joint>
  <link name="link_7">
    <inertial>
      <mass value="0.0388"/>
      <origin xyz="0 0 0" rpy="0 0 0"/>
      <inertia ixx="3.29223173333e-05" ixy="8.042076e-06" ixz="5.2283e-06" iyy="1.47493026667e-5" iyz="1.1283525e-5" izz="3.29223173333e-05"/>
    </inertial>
    <visual>
      <geometry>
        <mesh filename="../allegro_hand/meshes/visual/link_3.0.glb"/>
      </geometry>
    </visual>
    <collision>
      <geometry>
        <box size="0.0196 0.0269 0.022"/>
      </geometry>
      <origin rpy="0 0 0" xyz="0 0 0.0047"/>
    </collision>
  </link>
  <joint name="joint_7" type="revolute">
    <axis xyz="0 1 0"/>
    <limit effort="10" lower="-0.227" upper="1.618" velocity="3.14"/>
    <parent link="link_6"/>
    <child link="link_7"/>
    <origin xyz="0 0 0.0384"/>
  </joint>
  <link name="link_7_tip">
    <inertial>
      <mass value="0.0096"/>
      <origin xyz="0 0 0" rpy="0 0 0"/>
      <inertia ixx="4.701248e-06" ixy="1.255968e-06" ixz="1.2936e-06" iyy="3.649312e-06" iyz="1.7622e-06" izz="4.701248e-06"/>
    </inertial>
    <visual>
      <geometry>
        <mesh filename="../allegro_hand/meshes/visual/link_tip.glb"/>
      </geometry>
    </visual>
    <collision>
      <geometry>
        <mesh filename="../allegro_hand/meshes/collision/link_tip.obj"/>
      </geometry>
    </collision>
  </link>
  <joint name="joint_7_tip" type="fixed">
    <parent link="link_7"/>
    <child link="link_7_tip"/>
    <origin rpy="0 0 0" xyz="0 0 0.0267"/>
  </joint>
  <link name="link_8">
    <inertial>
      <mass value="0.005"/>
      <origin xyz="0 0 0"/>
      <inertia ixx="5.1458e-05" iyy="5.1458e-05" izz="6.125e-05" ixy="0" ixz="0" iyz="0"/>
    </inertial>
    <visual>
      <geometry>
        <mesh filename="../allegro_hand/meshes/visual/link_0.0.glb"/>
      </geometry>
    </visual>
    <collision>
      <geometry>
        <box size="0.0196 0.0275 0.0164"/>
      </geometry>
      <origin rpy="0 0 0" xyz="0 0 0.0082"/>
    </collision>
  </link>
  <joint name="joint_8" type="revolute">
    <axis xyz="0 0 1"/>
    <limit effort="10" lower="-0.47" upper="0.47" velocity="3.14"/>
    <parent link="base_link_hand"/>
    <child link="link_8"/>
    <origin rpy="0.08726646255 0 0" xyz="0 -0.0435 -0.001542"/>
  </joint>
  <link name="link_9">
    <inertial>
      <mass value="0.065"/>
      <origin xyz="0 0 0" rpy="0 0 0"/>
      <inertia ixx="7.95654166667e-05" ixy="1.7199e-05" ixz="8.75875e-06" iyy="2.47088833333e-05" iyz="2.413125e-05" izz="7.95654166667e-05"/>
    </inertial>
    <visual>
      <geometry>
        <mesh filename="../allegro_hand/meshes/visual/link_1.0.glb"/>
      </geometry>
    </visual>
    <collision>
      <geometry>
        <box size="0.0196 0.0275 0.054"/>
      </geometry>
      <origin rpy="0 0 0" xyz="0 0 0.027"/>
    </collision>
  </link>
  <joint name="joint_9" type="revolute">
    <limit effort="10" lower="-0.196" upper="1.61" velocity="3.14"/>
    <axis xyz="0 1 0"/>
    <parent link="link_8"/>
    <child link="link_9"/>
    <origin xyz="0 0 0.0164"/>
  </joint>
  <link name="link_10">
    <inertial>
      <mass value="0.0355"/>
      <origin xyz="0 0 0" rpy="0 0 0"/>
      <inertia ixx="2.63979183333e-05" ixy="6.67968e-06" ixz="4.783625e-06" iyy="1.34948516667e-05" iyz="9.372e-06" izz="2.63979183333e-05"/>
    </inertial>
    <visual>
      <geometry>
        <mesh filename="../allegro_hand/meshes/visual/link_2.0.glb"/>
      </geometry>
    </visual>
    <collision>
      <geometry>
        <box size="0.0196 0.0275 0.0384"/>
      </geometry>
      <origin rpy="0 0 0" xyz="0 0 0.0192"/>
    </collision>
  </link>
  <joint name="joint_10" type="revolute">
    <axis xyz="0 1 0"/>
    <limit effort="10" lower="-0.174" upper="1.709" velocity="3.14"/>
    <parent link="link_9"/>
    <child link="link_10"/>
    <origin xyz="0 0 0.054"/>
  </joint>
  <link name="link_11">
    <inertial>
      <mass value="0.0096"/>
      <origin xyz="0 0 0" rpy="0 0 0"/>
      <inertia ixx="4.701248e-06" ixy="1.255968e-06" ixz="1.2936e-06" iyy="3.649312e-06" iyz="1.7622e-06" izz="4.701248e-06"/>
    </inertial>
    <visual>
      <geometry>
        <mesh filename="../allegro_hand/meshes/visual/link_3.0.glb"/>
      </geometry>
    </visual>
    <collision>
      <geometry>
        <box size="0.0196 0.0269 0.022"/>
      </geometry>
      <origin rpy="0 0 0" xyz="0 0 0.0047"/>
    </collision>
  </link>
  <joint name="joint_11" type="revolute">
    <axis xyz="0 1 0"/>
    <limit effort="10" lower="-0.227" upper="1.618" velocity="3.14"/>
    <parent link="link_10"/>
    <child link="link_11"/>
    <origin xyz="0 0 0.0384"/>
  </joint>
  <link name="link_11_tip">
    <inertial>
      <mass value="0.0168"/>
      <origin xyz="0 0 0" rpy="0 0 0"/>
      <inertia ixx="9.68e-07" ixy="0" ixz="0" iyy="9.68e-07" iyz="0" izz="9.68e-07"/>
    </inertial>
    <visual>
      <geometry>
        <mesh filename="../allegro_hand/meshes/visual/link_tip.glb"/>
      </geometry>
    </visual>
    <collision>
      <geometry>
        <mesh filename="../allegro_hand/meshes/collision/link_tip.obj"/>
      </geometry>
    </collision>
  </link>
  <joint name="joint_11_tip" type="fixed">
    <parent link="link_11"/>
    <child link="link_11_tip"/>
    <origin rpy="0 0 0" xyz="0 0 0.0267"/>
  </joint> <!-- THUMB -->
  <link name="link_12">
    <inertial>
      <mass value="0.0176"/>
      <origin xyz="0 0 0" rpy="0 0 0"/>
      <inertia ixx="1.89273333333e-5" ixy="7.16716e-06" ixz="5.35568e-06" iyy="1.43008213333e-05" iyz="6.8068e-06" izz="1.89273333333e-05"/>
    </inertial>
    <visual>
      <geometry>
        <mesh filename="../allegro_hand/meshes/visual/link_12.0_right.glb"/>
      </geometry>
    </visual>
    <collision>
      <geometry>
        <box size="0.0358 0.034 0.0455"/>
      </geometry>
      <origin rpy="0 0 0" xyz="-0.0179 0.009 0.0145"/>
    </collision>
  </link>
  <joint name="joint_12" type="revolute">
    <axis xyz="-1 0 0"/>
    <limit effort="10" lower="0.263" upper="1.396" velocity="3.14"/>
    <parent link="base_link_hand"/>
    <child link="link_12"/>
    <origin rpy="0 -1.65806278845 -1.5707963259" xyz="-0.0182 0.019333 -0.045987"/>
  </joint>
  <link name="link_13">
    <inertial>
      <mass value="0.0119"/>
      <origin xyz="0 0 0" rpy="0 0 0"/>
      <inertia ixx="4.24250866667e-06" ixy="1.032087e-06" ixz="1.603525e-06" iyy="4.52362633333e-06" iyz="1.44808125e-06" izz="4.24250866667e-06"/>
    </inertial>
    <visual>
      <geometry>
        <mesh filename="../allegro_hand/meshes/visual/link_13.0.glb"/>
      </geometry>
    </visual>
    <collision>
      <geometry>
        <box size="0.0196 0.0275 0.0177"/>
      </geometry>
      <origin rpy="0 0 0" xyz="0 0 0.00885"/>
    </collision>
  </link>
  <joint name="joint_13" type="revolute">
    <axis xyz="0 0 1"/>
    <limit effort="10" lower="-0.105" upper="1.163" velocity="3.14"/>
    <parent link="link_12"/>
    <child link="link_13"/>
    <origin xyz="-0.027 0.005 0.0399"/>
  </joint>
  <link name="link_14">
    <inertial>
      <mass value="0.038"/>
      <origin xyz="0 0 0" rpy="0 0 0"/>
      <inertia ixx="4.30439933333e-05" ixy="9.57068e-06" ixz="5.1205e-06" iyy="1.44451933333e-05" iyz="1.342825e-05" izz="4.30439933333e-05"/>
    </inertial>
    <visual>
      <geometry>
        <mesh filename="../allegro_hand/meshes/visual/link_14.0.glb"/>
      </geometry>
    </visual>
    <collision>
      <geometry>
        <box size="0.0196 0.0275 0.0514"/>
      </geometry>
      <origin rpy="0 0 0" xyz="0 0 0.0257"/>
    </collision>
  </link>
  <joint name="joint_14" type="revolute">
    <axis xyz="0 1 0"/>
    <limit effort="10" lower="-0.189" upper="1.644" velocity="3.14"/>
    <parent link="link_13"/>
    <child link="link_14"/>
    <origin xyz="0 0 0.0177"/>
  </joint>
  <link name="link_15">
    <inertial>
      <mass value="0.0388"/>
      <origin xyz="0 0 0" rpy="0 0 0"/>
      <inertia ixx="3.29223173333e-05" ixy="8.042076e-06" ixz="5.2283e-06" iyy="1.47493026667e-5" iyz="1.1283525e-5" izz="3.29223173333e-05"/>
    </inertial>
    <visual>
      <geometry>
        <mesh filename="../allegro_hand/meshes/visual/link_15.0.glb"/>
      </geometry>
    </visual>
    <collision>
      <geometry>
        <box size="0.0196 0.0269 0.04"/>
      </geometry>
      <origin rpy="0 0 0" xyz="0 0 0.01125"/>
    </collision>
  </link>
  <joint name="joint_15" type="revolute">
    <axis xyz="0 1 0"/>
    <limit effort="10" lower="-0.162" upper="1.719" velocity="3.14"/>
    <parent link="link_14"/>
    <child link="link_15"/>
    <origin xyz="0 0 0.0514"/>
  </joint>
  <link name="link_15_tip">
    <inertial>
      <mass value="0.0168"/>
      <origin xyz="0 0 0" rpy="0 0 0"/>
      <inertia ixx="9.68e-07" ixy="0" ixz="0" iyy="9.68e-07" iyz="0" izz="9.68e-07"/>
    </inertial>
    <visual>
      <geometry>
        <mesh filename="../allegro_hand/meshes/visual/link_tip.glb"/>
      </geometry>
    </visual>
    <collision>
      <geometry>
        <mesh filename="../allegro_hand/meshes/collision/link_tip.obj"/>
      </geometry>
    </collision>
  </link>
  <joint name="joint_15_tip" type="fixed">
    <parent link="link_15"/>
    <child link="link_15_tip"/>
    <origin rpy="0 0 0" xyz="0 0 0.0423"/>
  </joint>

</robot>
