<?xml version="1.0"?>
<robot name="laptop_model_single_hinge_corrected">

  <link name="global_base" />
  <joint name="global_rotation" type="fixed">

    <origin xyz="0 0 0" rpy="0 0 1.5708"/>
    <parent link="global_base"/>
    <child link="base_link"/>
  </joint>

  
  <link name="base_link">
    <visual>
      <origin xyz="0 0 0.01" rpy="0 0 0"/>
      <geometry>
        <box size="0.30 0.20 0.02"/>
      </geometry>
      <material name="gray"/>
    </visual>
    <collision>
      <origin xyz="0 0 0.01" rpy="0 0 0"/>
      <geometry>
        <box size="0.30 0.20 0.02"/>
      </geometry>
    </collision>
    <inertial>
      <mass value="1.0"/>
      <origin xyz="0 0 0.01" rpy="0 0 0"/>
      <inertia ixx="0.01" ixy="0" ixz="0" iyy="0.01" iyz="0" izz="0.01"/>
    </inertial>
  </link>

  <joint name="hinge_joint" type="revolute">
 
    <origin xyz="0 -0.10 0.02" rpy="0 0 0"/>
    <parent link="base_link"/>
    <child link="screen_link"/>
    <axis xyz="1 0 0"/>
    <limit lower="-1.57" upper="1.57" effort="4.0" velocity="2.0"/>
    <dynamics damping="20" friction="30"/>
  </joint>

  <link name="screen_link">
    <visual>
      <origin xyz="0 0 0.11" rpy="0 0 0"/>
      <geometry>
        <box size="0.30 0.01 0.20"/>
      </geometry>
      <material name="black"/>
    </visual>
    <collision>
      <origin xyz="0 0 0.11" rpy="0 0 0"/>
      <geometry>
        <box size="0.30 0.01 0.20"/>
      </geometry>
    </collision>
    <inertial>
      <mass value="0.05"/>
      <origin xyz="0 0 0.10" rpy="0 0 0"/>
      <inertia ixx="0.005" ixy="0" ixz="0" iyy="0.005" iyz="0" izz="0.005"/>
    </inertial>
  </link>

</robot>
