<?xml version="1.0"?>
<robot name="faucet_model_rotated">

  <link name="global_base" />


  <joint name="global_rotation" type="fixed">

    <origin xyz="0 0 0" rpy="0 0 3.14159"/>
    <parent link="global_base"/>
    <child link="base_link"/>
  </joint>


  <link name="base_link">
    <visual>
      <origin xyz="0 0 0.0025" rpy="0 0 0"/>
      <geometry>
        <cylinder radius="0.05" length="0.005"/>
      </geometry>
      <material name="gray"/>
    </visual>
    <collision>
      <origin xyz="0 0 0.0025" rpy="0 0 0"/>
      <geometry>
        <cylinder radius="0.05" length="0.005"/>
      </geometry>
    </collision>
    <inertial>
      <mass value="0.1"/>
      <origin xyz="0 0 0.0025" rpy="0 0 0"/>
      <inertia ixx="1e-4" ixy="0" ixz="0" iyy="1e-4" iyz="0" izz="1e-4"/>
    </inertial>
  </link>


  <link name="main_body">
    <visual>
      <origin xyz="0 0 0.075" rpy="0 0 0"/>
      <geometry>
        <cylinder radius="0.025" length="0.13"/>
      </geometry>
      <material name="silver"/>
    </visual>
    <collision>
      <origin xyz="0 0 0.075" rpy="0 0 0"/>
      <geometry>
        <cylinder radius="0.025" length="0.13"/>
      </geometry>
    </collision>
    <inertial>
      <mass value="0.2"/>
      <origin xyz="0 0 0.075" rpy="0 0 0"/>
      <inertia ixx="1e-4" ixy="0" ixz="0" iyy="1e-4" iyz="0" izz="1e-4"/>
    </inertial>
  </link>

  <joint name="joint_base_to_body" type="fixed">
    <origin xyz="0 0 0.005" rpy="0 0 0"/>
    <parent link="base_link"/>
    <child link="main_body"/>
  </joint>

 
  <link name="spout_link">
    <visual>
      <origin xyz="0.05 0 0" rpy="0 -1.5708 0"/>
      <geometry>
        <cylinder radius="0.02" length="0.13"/>
      </geometry>
      <material name="blue"/>
    </visual>
    <collision>
      <origin xyz="0.05 0 0" rpy="0 -1.5708 0"/>
      <geometry>
        <cylinder radius="0.02" length="0.13"/>
      </geometry>
    </collision>
    <visual>
      <origin xyz="0.1 0 -0.02" rpy="0 0 0"/>
      <geometry>
        <cylinder radius="0.015" length="0.02"/>
      </geometry>
      <material name="blue"/>
    </visual>
    <collision>
      <origin xyz="0.1 0 -0.02" rpy="0 0 0"/>
      <geometry>
        <cylinder radius="0.015" length="0.02"/>
      </geometry>
    </collision>
    <inertial>
      <mass value="0.1"/>
      <origin xyz="0.075 0 0.005" rpy="0 0 0"/>
      <inertia ixx="1e-4" ixy="0" ixz="0" iyy="1e-4" iyz="0" izz="1e-4"/>
    </inertial>
  </link>

  
  <joint name="joint_body_to_spout" type="fixed">
    <origin xyz="0 0 0.08" rpy="0 0 0"/>
    <parent link="main_body"/>
    <child link="spout_link"/>
  </joint>


  <link name="top_link">
    <visual>
      <origin xyz="0 0 0.02" rpy="0 0 0"/>
      <geometry>
        <cylinder radius="0.025" length="0.04"/>
      </geometry>
      <material name="silver"/>
    </visual>
    <collision>
      <origin xyz="0 0 0.02" rpy="0 0 0"/>
      <geometry>
        <cylinder radius="0.025" length="0.04"/>
      </geometry>
    </collision>
    <inertial>
      <mass value="0.1"/>
      <origin xyz="0 0 0.02" rpy="0 0 0"/>
      <inertia ixx="1e-4" ixy="0" ixz="0" iyy="1e-4" iyz="0" izz="1e-4"/>
    </inertial>
  </link>

 
  <joint name="joint_body_to_top" type="revolute">
    <origin xyz="0 0 0.13" rpy="0 0 0"/>
    <parent link="main_body"/>
    <child link="top_link"/>
    <axis xyz="0 0 1"/>
    <limit lower="-1.7" upper="1.7" effort="5.0" velocity="2.0"/>
  </joint>


  <link name="handle_link">
    <visual>
      <origin xyz="0.035 0 0" rpy="0 -1.5708 0"/>
      <geometry>
        <cylinder radius="0.0045" length="0.12"/>
      </geometry>
      <material name="black"/>
    </visual>
    <collision>
      <origin xyz="0.035 0 0" rpy="0 -1.5708 0"/>
      <geometry>
        <cylinder radius="0.0045" length="0.12"/>
      </geometry>
    </collision>
    <inertial>
      <mass value="0.001"/>
      <origin xyz="0.035 0 0" rpy="0 0 0"/>
      <inertia ixx="1e-6" ixy="0" ixz="0" iyy="1e-6" iyz="0" izz="1e-6"/>
    </inertial>
  </link>

 
  <joint name="joint_top_to_handle" type="fixed">
    <origin xyz="0 0 0.025" rpy="0 0 0"/>
    <parent link="top_link"/>
    <child link="handle_link"/>
  </joint>

</robot>
